Workbook

Sheet Analytics
A1: Business Name | B1: Business ID
A2: Falafel Corner
A3: Taystee's Burgers
A4: Hogsalt

Sheet Social Media 
A1: Emails | B1: Business ID | C1: Cuisine | D1: Business Name | E1: Instagram Shared? | F1: Events Shared? | G1: First Set of Posts Generated? | H1: Social Media LInk | I1: # of Followers | J1: Photos and Videos? | K1: Engagement Level | L1: Comments | M1: MP Weekly Avg | N1: SF Weekly Avg
A2: julianlosocampo@gmail.com | B2: 16914 | C2: healthy,guacamole,chips_and_salsa,steak,pollo_la_brasa,chicken_shop,al_pastor,carne_asada,enchiladas,tacos,burritos,quesadillas,bars,mexican | D2: Los Ocampos | E2: No | H2: https://www.instagram.com/losocamporestaurants/ | I2: 2840 | J2: photos and vids | K2: Low | L2: influencer videos, photos, | M2: 960.8 | N2: 190.9
A3: lisandro@glenteamre.com | B3: 14600429 | C3: burritos,mexican,tacos | D3: La Cocina | E3: Yes | F3: Yes | G3: 1. Lunch special 11-2 Lunch Pork or chicken with rice and free soda Starting at 9.99 2. St Patty's 3. Menu item highlight Mofongo | H3: https://www.instagram.com/lacocina_nj/?hl=en | I3: 8598 | J3: photos and vids | K3: Low | L3: Do boosted content, sponsored listings, posts every day, haven't seem to cracked the code | M3: 231 | N3: 9.1
A4: art4foodinc@gmail.com | B4: 9186 | C4: dineout-new,burgers,fast_casual,fast_food,fried_chicken,comfort_food,american | D4: Burger Bun | E4: Yes | F4: Not Yet need to ask | G4: 1. March Madness 2. 10AM -11AM Early Bird special in person only or for phone pickup 15% off everything 3. 8 PM - 10 PM Happy Hour TBD | H4: https://www.instagram.com/burgerbunla/ | I4: 2422 | J4: photos and some vids | K4: Low | L4: High quality videos | M4: 283.9 | N4: 4.1
A5: mastoory@tasteofchelo.com | B5: 547263 | C5: mediterranean,middle_east | D5: Chelo | H5: https://www.instagram.com/tasteofchelo/ | I5: 7391 | J5: photos vids | K5: Low | L5: Good to work with, wants to share, easy to join, get catering | M5: 24.2 | N5: 0.3
A6: sumoramen88@gmail.com | B6: 142325 | C6: fast_food,comfort_food,japanese | D6: Sumo Ramen Market City | H6: https://www.instagram.com/sumoramenmarketcity/ | I6: 88 | J6: photos | K6: Low | L6: only 2 posts, no engagement | M6: 157 | N6: 1
A7: jaliscoscateringservices@gmail.com | B7: 13986555 | C7: seafood_restaurant,casual_dining,mexican | D7: Jalisco Restaurant Authentic Mexican Food | H7: https://www.instagram.com/jaliscoscatering/ | I7: 66 | J7: photos and vids | K7: Low | M7: 100.7 | N7: 0.8
A8: admin@falafelcorner.us | B8: 1386 | C8: fast_food,mediterranean,middle_eastern | D8: Falafel Corner | H8: https://www.instagram.com/falafelcornerdowntown/?hl=en | I8: 445 | J8: photos and vids | K8: Low | L8: No show | M8: 1806 | N8: 129.1
A9: teejayescountryplace@gmail.com | B9: 26715 | C9: comfort_food,miami_deli,soup,salads,sandwich | D9: Tee Jayes Country Place | H9: https://www.instagram.com/teejayescountryplace/ | I9: 1035 | J9: photos | K9: Low | L9: Updates, promos, some menu items | M9: 951.2 | N9: 70.9
A10: sigmabid@gmail.com | B10: 12917793 | C10: fast_food,halal | D10: Halal Express | H10: https://www.instagram.com/halalexpressnj/ | I10: 1281 | J10: videos | K10: Low | L10: they post really good, food focused videos but still doesn't get any engagement | M10: 337 | N10: 13.3
A11: tionachonyc@outlook.com | B11: 69204 | C11: sandwiches,dessert_and_fast-food,smoothies,breakfast,mexican | D11: Tio Nacho | H11: https://www.instagram.com/tionacho_nyc/?hl=en | I11: 207 | J11: photos and vids | K11: Low | L11: Engaged merchant, easy to work with, interested in the pilot for sure | M11: 105.5 | N11: 5.6
A12: 323hibachigrill@gmail.com, ruben.gallegos97@gmail.com | B12: 11350087 | C12: salmon,burgers,bars,hibachi,japanese | D12: 323 Hibachi Grill | H12: https://www.instagram.com/323hibachigrill/ | I12: 15800 | J12: photos and vids | K12: Med/high | L12: Friendly merchant, does well with influencer posts, success is increased order volume | M12: 286.5 | N12: 13.6
A13: contact@tetsujinsushi.com | B13: 157602 | C13: vegetarian,fast_casual,cheesesteaks,sandwiches,shrimp,chicken_shop,chicken_wings,wings,seafood_restaurant,american | D13: Kaisen Don (Balboa St) | Kaisen Don | H13: https://www.instagram.com/kaisendon1939/ | I13: 15700 | J13: photos and vids | K13: Low | L13: does influencer marketing, video | M13: 272 | N13: 153.7
A14: nthepmanee@thaicortez.com | B14: 11744651 | C14: casual_dining,thai | D14: Thai Cortez | H14: https://www.instagram.com/thai.cortez/ | I14: 64 | J14: photos and vids | K14: Low | L14: Friendly merchant, definitely needs help to increase instagram usage but population is typically older, only posts videos of food here and there | M14: 41.2 | N14: 40.7

Sheet SEO Blogs
A1: Business Name | C1: Business ID | D1: Email | E1: Website | F1: Keywords | G1: Weekly MP Vol | H1: SF Vol | I1: SF OSW | J1: Organic Vol | K1: GFO Vol | L1: AOV | M1: Notes
A2: 161030 | B2: =CONCATENATE(A2,",") -> 161030, | C2: Taichi Bubble Tea | D2: =VLOOKUP(A2,Sheet5!A:D,4,FALSE) -> taichibubbletea@gmail.com | F2: =IFERROR(VLOOKUP(C:C,Sheet1!A:C,2,false),"") | G2: 6464 | H2: 1971 | I2: 36.5 | J2: 1766 | K2: 205 | L2: 26.4 | M2: Mohamad Elgendi | N2: =IFERROR(VLOOKUP(C:C,#REF!,4,false),"") | O2: =IFERROR(VLOOKUP(C:C,#REF!,6,false),"")
A3: 35243 | B3: =CONCATENATE(A3,",") -> 35243, | C3: Yoshiharu Ramen | D3: =VLOOKUP(A3,Sheet5!A:D,4,FALSE) -> admin@yoshiharuramen.com | F3: =IFERROR(VLOOKUP(A:A,Sheet1!A:C,2,false),"") | G3: 579 | H3: 250 | I3: =H3/#REF! -> #REF! | J3: 249 | K3: 1 | L3: 39.2 | M3: Mohamad Elgendi can reach out | N3: =IFERROR(VLOOKUP(A:A,#REF!,3,false),"")
A4: 1386 | B4: =CONCATENATE(A4,",") -> 1386, | C4: Falafel Corner | D4: =VLOOKUP(A4,Sheet5!A:D,4,FALSE) -> bilalahmad8365@gmail.com | E4: https://fcorner.com/ | F4: =IFERROR(VLOOKUP(A:A,Sheet1!A:C,2,false),"") | G4: 1750 | H4: 18 | I4: 202 | J4: 18 | K4: =I4/J4 -> 11.222222 | L4: 164 | M4: Mohamad Elgendi can reach out | N4: =IFERROR(VLOOKUP(A:A,#REF!,3,false),"")
A5: 631205 | B5: =CONCATENATE(A5,",") -> 631205, | C5: Tacos El Regio | D5: =VLOOKUP(A5,Sheet5!A:D,4,FALSE) -> tacoselregionacogdoches@gmail.com | F5: =IFERROR(VLOOKUP(A:A,Sheet1!A:C,2,false),"") | G5: 802 | H5: 49 | I5: =H5/#REF! -> #REF! | J5: 40 | K5: 9 | L5: 24.45 | M5: Mohamad Elgendi | N5: =IFERROR(VLOOKUP(A:A,#REF!,3,false),"")
A6: 626500 | B6: =CONCATENATE(A6,",") -> 626500, | C6: Shawarma King | D6: =VLOOKUP(A6,Sheet5!A:D,4,FALSE) -> mohsoliman1@gmail.com | F6: =IFERROR(VLOOKUP(A:A,Sheet1!A:C,2,false),"") | G6: 478 | H6: 48 | I6: =H6/#REF! -> #REF! | J6: 31 | K6: 17 | L6: 26.61 | M6: Mohamad Elgendi | N6: =IFERROR(VLOOKUP(A:A,#REF!,3,false),"")
A7: 11781480 | B7: =CONCATENATE(A7,",") -> 11781480, | C7: Owl Breakfast & Lunch | D7: =VLOOKUP(A7,Sheet5!A:D,4,FALSE) -> owlbreakfastlunchcecilbmooreave@owlbreakoperations.com | F7: =IFERROR(VLOOKUP(A:A,Sheet1!A:C,2,false),"") | G7: 491 | H7: 80 | I7: =H7/#REF! -> #REF! | J7: 64 | K7: 16 | L7: 20.76 | M7: Say their website is beautiful | N7: =IFERROR(VLOOKUP(A:A,#REF!,3,false),"")
A8: 51964 | B8: =CONCATENATE(A8,",") -> 51964, | C8: Lucifer's Pizza | D8: =VLOOKUP(A8,Sheet5!A:D,4,FALSE) -> adam@luciferspizza.com | F8: =IFERROR(VLOOKUP(A:A,Sheet1!A:C,2,false),"") | G8: 419 | H8: 5 | I8: 217 | J8: 5 | K8: =I8/J8 -> 43.4 | L8: 213 | N8: =IFERROR(VLOOKUP(A:A,#REF!,3,false),"")
A9: 421348 | B9: =CONCATENATE(A9,",") -> 421348, | C9: JaxSpice | D9: =VLOOKUP(A9,Sheet5!A:D,4,FALSE) -> jaxspicefamily@gmail.com | F9: =IFERROR(VLOOKUP(A:A,Sheet1!A:C,2,false),"") | G9: 273 | H9: 146 | I9: =H9/#REF! -> #REF! | J9: 124 | K9: 22 | L9: 52.17 | N9: =IFERROR(VLOOKUP(A:A,#REF!,3,false),"")
A10: 11428387 | B10: =CONCATENATE(A10,",") -> 11428387, | C10: 8 Bit Bites | D10: =VLOOKUP(A10,Sheet5!A:D,4,FALSE) -> ammar.algaradi@outlook.com | F10: =IFERROR(VLOOKUP(A:A,Sheet1!A:C,2,false),"") | G10: 241 | H10: 67 | I10: =H10/#REF! -> #REF! | J10: 48 | K10: 19 | L10: 29.01 | N10: =IFERROR(VLOOKUP(A:A,#REF!,3,false),"")
A11: 362296 | B11: =CONCATENATE(A11,",") -> 362296, | C11: Sea Salt Healthy Kitchen | D11: =VLOOKUP(A11,Sheet5!A:D,4,FALSE) -> seasalthealthykitchen19@gmail.com | F11: =IFERROR(VLOOKUP(A:A,Sheet1!A:C,2,false),"") | G11: 62 | H11: 67 | I11: =H11/#REF! -> #REF! | J11: 53 | K11: 14 | L11: 35.77 | N11: =IFERROR(VLOOKUP(A:A,#REF!,3,false),"")
A12: 14667011 | B12: =CONCATENATE(A12,",") -> 14667011, | C12: Dude’s Chicken (Halal) | D12: =VLOOKUP(A12,Sheet5!A:D,4,FALSE) -> khalid@dudeschicken.com | F12: =IFERROR(VLOOKUP(A:A,Sheet1!A:C,2,false),"") | G12: 124 | H12: 66 | I12: =H12/#REF! -> #REF! | J12: 66 | K12: 0 | L12: 31
A13: 212844 | B13: =CONCATENATE(A13,",") -> 212844, | C13: Petra Mediterranean Cuisine | D13: =VLOOKUP(A13,Sheet5!A:D,4,FALSE) -> cafealaddins@yahoo.com | G13: 63 | H13: 33 | I13: 33 | J13: 28 | K13: 5 | L13: 39.18
A14: 286030 | B14: =CONCATENATE(A14,",") -> 286030, | C14: Taqueria El Cazador | D14: =VLOOKUP(A14,Sheet5!A:D,4,FALSE) -> puandro@gmail.com | G14: 594 | H14: 32 | I14: 4 | J14: 16 | K14: 16 | L14: 28
A15: 208622 | B15: =CONCATENATE(A15,",") -> 208622, | C15: Pizza Bar South Beach | D15: =VLOOKUP(A15,Sheet5!A:D,4,FALSE) -> mcuza@bodegataqueria.com | G15: 103 | H15: 31 | I15: 31 | J15: 28 | K15: 3 | L15: 37.66
A16: 88865 | B16: =CONCATENATE(A16,",") -> 88865, | C16: Burger Bros | D16: =VLOOKUP(A16,Sheet5!A:D,4,FALSE) -> contactrealdreamllc@gmail.com | G16: 292 | H16: 30 | I16: 30 | J16: 27 | K16: 3 | L16: 29
A17: 1064355 | B17: =CONCATENATE(A17,",") -> 1064355, | C17: Happy House Chinese Food (Memorial location) | D17: =VLOOKUP(A17,Sheet5!A:D,4,FALSE) -> zhuzaiyun1981@gmail.com | G17: 125 | H17: 30 | I17: 30 | J17: 27 | K17: 3 | L17: 33.95
A18: 11359240 | B18: =CONCATENATE(A18,",") -> 11359240, | C18: Halal Burgers & More | D18: =VLOOKUP(A18,Sheet5!A:D,4,FALSE) -> halalburgersmore@gmail.com | G18: 767 | H18: 29 | I18: 29 | J18: 16 | K18: 13 | L18: 23.2
A19: 11624201 | B19: =CONCATENATE(A19,",") -> 11624201, | C19: Pho Hoang | D19: =VLOOKUP(A19,Sheet5!A:D,4,FALSE) -> nguy127@gmail.com | G19: 235 | H19: 27 | I19: 27 | J19: 27 | K19: 0 | L19: 34.75
A20: 226380 | B20: =CONCATENATE(A20,",") -> 226380, | C20: Philly's A Taste Of Philadelphia | D20: =VLOOKUP(A20,Sheet5!A:D,4,FALSE) -> thephillystop@gmail.com | G20: 134 | H20: 26 | I20: 8.7 | J20: 23 | K20: 3 | L20: 32.23
A21: 12961250 | B21: =CONCATENATE(A21,",") -> 12961250, | C21: Taco De Oro | D21: =VLOOKUP(A21,Sheet5!A:D,4,FALSE) -> elbotascano@gmail.com | G21: 58 | H21: 26 | I21: 6.5 | J21: 20 | K21: 6 | L21: 24.57
A22: 273840 | B22: =CONCATENATE(A22,",") -> 273840, | C22: 7 Star Pizza | D22: =VLOOKUP(A22,Sheet5!A:D,4,FALSE) -> 7177201@gmail.com | G22: 53 | H22: 26 | I22: 26 | J22: 26 | K22: 0 | L22: 27.08
A23: 13635899 | B23: =CONCATENATE(A23,",") -> 13635899, | C23: China Moon | D23: =VLOOKUP(A23,Sheet5!A:D,4,FALSE) -> andyye0730@gmail.com | G23: 135 | H23: 25 | I23: 25 | J23: 19 | K23: 6 | L23: 32.09
A24: 11197655 | B24: =CONCATENATE(A24,",") -> 11197655, | C24: ShakeBacks | D24: =VLOOKUP(A24,Sheet5!A:D,4,FALSE) -> shakebackslaf@yahoo.com | G24: 200 | H24: 24 | I24: 24 | J24: 19 | K24: 5 | L24: 27.07

Sheet Sheet5
A1: BUSINESS_ID | B1: FIRST_NAME | C1: LAST_NAME | D1: EMAIL_ADDRESS | E1: ROLE | F1: STORE_ACCESS_STORE_IDS | G1: STORE_ACCESS_STORE_NAMES | H1: LAST_UPDATED
A2: 1386 | B2: Bilal | C2: Ahmad | D2: bilalahmad8365@gmail.com | E2: MANAGER | F2: 29303024 | G2: Falafel Corner (Lodi) | H2: 46063.641
A3: 1386 | B3: Humayon | C3: Ahmad | D3: humayonahmad23@gmail.com | E3: MANAGER | F3: 23078422 | G3: Falafel Corner (Davis) | H3: 46063.641
A4: 1386 | B4: Riaz | C4: Ahmad | D4: woodlandfalafel@gmail.com | E4: MANAGER | F4: 2.3078422e+15 | G4: Falafel Corner (Davis) | Falafel Corner (Gibson Rd) | H4: 46063.641
A5: 1386 | B5: Aqeel | C5: Ahmad | D5: ab.corner@yahoo.com | E5: MANAGER | F5: 30345666 | G5: Falafel Corner (Travis Blvd) | H5: 46063.641
A6: 1386 | B6: Touqeer | C6: Ahmed | D6: falafelcornerelkgrove@gmail.com | E6: MANAGER | F6: 782936 | G6: Falafel Corner (Bruceville) | H6: 46063.641
A7: 1386 | B7: Touqeer | C7: Ahmed | D7: rehmantouqeer@yahoo.com | E7: MANAGER | F7: 1212307 | G7: Falafel Corner (Alhambra Blvd) | H7: 46063.641
A8: 1386 | B8: Touqeer | C8: Ahmed | D8: tookie1andonly@gmail.com | E8: MANAGER | F8: 1212307782936 | G8: Falafel Corner (Bruceville) | Falafel Corner (Alhambra Blvd) | H8: 46063.641
A9: 1386 | B9: Saad | C9: Asghar | D9: falafelcornerbrentwood@gmail.com | E9: ADMIN | F9: 1653154 | G9: Falafel Corner (Brentwood Blvd) | H9: 46063.641
A10: 1386 | B10: Saif | C10: Aslam | D10: falafelcornerjst@gmail.com | E10: ADMIN | F10: 611860 | G10: Falafel Corner (J Street) - Drive | H10: 46063.641
A11: 1386 | B11: Falafel | C11: Corner | D11: fcdavis720@gmail.com | E11: MANAGER | F11: 23078422 | G11: Falafel Corner (Davis) | H11: 46063.641
A12: 1386 | B12: Falafel | C12: Corner | D12: fcornerguys@gmail.com | E12: MANAGER | F12: 564228 | G12: Falafel Corner (Bradshaw Rd) | H12: 46063.641
A13: 1386 | B13: Livinity | C13: Freeport | D13: livinityfreeport@gmail.com | E13: MANAGER | F13: 30913283 | G13: Falafel Corner (Freeport Blvd) | H13: 46063.641
... A62: 161030 | B62: xin | C62: chen | D62: taichibubbletea78@gmail.com | E62: MANAGER | F62: 24328608 | G62: Taichi Bubble Tea (Transit Road) | H62: 46063.641
A63: 161030 | B63: Zining | C63: Chen | D63: zining.taichitea@gmail.com | E63: ADMIN | F63: 34631365,785645,26008539,24603135,24686949,40446895,35540217,30086866,24886734,1549392,2816422,308244,23366616,25104749,24328608,24165589,25487498,32844989,33738137,2512429,1808650,801843,25308292,23177241,39734083,28236597,1595762,24337081,26288605,30923400,31565371,1083912,27678121,24463485,30178546,772709,2816430,34449285,40446697,970661,30702433,30320691,25055566,25806593,702897,1186559,757275,24603182,23550888,27810403,30979967,38204681,772550,38654725,24747397,33158695,23394272,34881545 | G63: Taichi Bubble Tea (Dewitt) | Taichi Bubble Tea (Glen Mills) | Taichi Bubble Tea (Exton) | Taichi Bubble Tea (Utica) | Taichi Bubble Tea (Broad St) | Taichi Bubble Tea (Pittsford) | Tai Chi Bubble Tea (Middletown) | Taichi Bubble Tea (Sioux Falls) | Taichi Bubble Tea (Crofton) | Taichi Bubble Tea (Georgetown) | Taichi Bubble Tea (Greece) | Taichi Bubble Tea (Marietta) | Taichi Bubble Tea (Stonybrook) | Taichi Bubble Tea (E Broadway Blvd) | Taichi Bubble Tea (Elmira) | Taichi Bubble Tea (Frederick) | Taichi Bubble Tea (Columbia Crossing Cir) | Taichi Bubble Tea (Ithaca) | Tai Chi Bubble Tea (North Ave) | Taichi Bubble Tea (Victor) | Taichi Bubble Tea (Peachtree Corners) | Taichi Bubble Tea (Bel Air) | Taichi Bubble Tea (Watkins Glen) | Taichi Bubble Tea (Annapolis) | Tai Chi Bubble Tea (E State St) | Taichi Bubble Tea (Watertown) | TaiChi Bubble Tea (E 3rd St) | Taichi Bubble Tea (New Haven) | Taichi Bubble Tea (Irondequoit) | Taichi Bubble Tea (Sykesville) | Taichi Bubble Tea (Decatur) | Tai Chi Bubble Tea (Woods Mill Plz) | Taichi Bubble Tea (Wichita) | Taichi Bubble Tea (Tonawanda) | Taichi Bubble Tea (Briarcliff Rd) | Taichi Bubble Tea (Nyack) | Taichi Bubble Tea/Ramen/Hibachi (Milwaukee) | Taichi Bubble Tea (Danbury) | Taichi Bubble Tea (Chicago) | Taichi Bubble Tea (Bronx) | Taichi Bubble Tea (Niagara Falls) | Taichi Bubble Tea (Mt Pleasant) | Taichi Bubble Tea (East Ave) | Taichi Bubble Tea (Vestal) | Taichi Bubble Tea, Ramen and Poke Bowl (Jacksonville) | Taichi Bubble Tea (Latham) | Taichi Bubble Tea (Henrietta) | Taichi Bubble Tea (Jackson) | Taichi Bubble Tea (UA Albany) | Taichi Bubble Tea (Mt. Prospect) | Taichi Bubble Tea (Sacramento) | Taichi Bubble Tea (Provo) | Taichi Bubble Tea (College Town) | Taichi Bubble Tea (Gunbarrel Rd) | Taichi Bubble Tea (Oklahoma City) | Taichi Bubble Tea (Syracuse) | Taichi Bubble Tea (Transit Road) | Taichi Bubble Tea (Severna Park) | H63: 46063.641
A64: 161030 | B64: Xiao | C64: Chen | D64: chenxy1979@gmail.com | E64: MANAGER | F64: 24747397 | G64: Taichi Bubble Tea (Georgetown) | H64: 46063.641
A65: 161030 | B65: Maggie | C65: Cheng | D65: mcds7986@gmail.com | E65: MANAGER | F65: 38204681 | G65: Tai Chi Bubble Tea (Woods Mill Plz) | H65: 46063.641
A66: 161030 | B66: Mengqiu | C66: Chi | D66: taichiteaithaca@gmail.com | E66: MANAGER | F66: 2816422 | G66: Taichi Bubble Tea (Ithaca) | H66: 46063.641
A67: 161030 | B67: Tai Chi Bubble Tea | C67: Employee | D67: bintaichitea@gmail.com | E67: MANAGER | F67: 1186559 | G67: Taichi Bubble Tea (Briarcliff Rd) | H67: 46063.641
A68: 161030 | B68: Tai Chi Bubble Tea | C68: Employee | D68: qingkexia@gmail.com | E68: MANAGER | F68: 7.725508e+23 | G68: Taichi Bubble Tea (Broad St) | Taichi Bubble Tea (Tonawanda) | Taichi Bubble Tea (College Town) | Taichi Bubble Tea (Henrietta) | H68: 46063.641
A69: 161030 | B69: Feng | C69: H | D69: taichichicago6800@gmail.com | E69: MANAGER | F69: 785645 | G69: Taichi Bubble Tea (Chicago) | H69: 46063.641
A70: 161030 | B70: Wayne | C70: Huang | D70: taichicolumbiainc@gmail.com | E70: ADMIN | F70: 24337081 | G70: Taichi Bubble Tea (Columbia Crossing Cir) | H70: 46063.641
A71: 161030 | B71: Zhi Qiang | C71: Huang | D71: niagarafallstaichi@gmail.com | E71: MANAGER | F71: 1083912 | G71: Taichi Bubble Tea (Niagara Falls) | H71: 46063.641
A72: 161030 | B72: Cindy | C72: Jiang | D72: dewitttaichi@gmail.com | E72: MANAGER | F72: 30923400 | G72: Taichi Bubble Tea (Dewitt) | H72: 46063.641
A73: 161030 | B73: John | C73: Jiang | D73: stonybrooktaichitea@gmail.com | E73: MANAGER | F73: 1595762 | G73: Taichi Bubble Tea (Stonybrook) | H73: 46063.641
A74: 161030 | B74: Li Feng | C74: Jiang | D74: jennyou2777@icloud.com | E74: ADMIN | F74: 27678121 | G74: Taichi Bubble Tea (Bronx) | H74: 46063.641
A75: 161030 | B75: Nichole | C75: Jiang | D75: lifengjiang1888@icloud.com | E75: MANAGER | F75: 27678121 | G75: Taichi Bubble Tea (Bronx) | H75: 46063.641
... A88: 161030 | B88: Owen | C88: Li | D88: taichiteadecatur@gmail.com | E88: MANAGER | F88: 33738137 | G88: Taichi Bubble Tea (Decatur) | H88: 46063.641
A89: 161030 | B89: Owen | C89: Li | D89: yijia.taichitea@gmail.com | E89: ADMIN | F89: 25104749,2512429,23550888,34881545,24463485,24747397,30178546,38204681,757275,25806593,25055566,23366616,28236597,30320691,772709,24328608,27810403,24337081,39734083,24165589,772550,1549392,27678121,32844989,23177241,2816430,31565371,35540217,785645,801843,30923400,33158695,1595762,26008539,40446697,34631365,702897,30086866,24603182,2816422,1808650,30979967,24886734,1186559,33738137,38654725,25487498,24603135,970661,1083912,40446895,23394272,24686949,30702433,25308292,308244,26288605,34449285 | G89: Taichi Bubble Tea (Mt. Prospect) | Taichi Bubble Tea (Oklahoma City) | Taichi Bubble Tea (Niagara Falls) | Taichi Bubble Tea (Greece) | Taichi Bubble Tea (Watertown) | Taichi Bubble Tea (Latham) | Taichi Bubble Tea (Gunbarrel Rd) | Tai Chi Bubble Tea (Middletown) | Taichi Bubble Tea (Frederick) | Taichi Bubble Tea (Danbury) | Taichi Bubble Tea (Elmira) | Taichi Bubble Tea (Exton) | Taichi Bubble Tea (Decatur) | Taichi Bubble Tea (East Ave) | Taichi Bubble Tea (E Broadway Blvd) | Taichi Bubble Tea, Ramen and Poke Bowl (Jacksonville) | Taichi Bubble Tea (Briarcliff Rd) | Tai Chi Bubble Tea (Woods Mill Plz) | Taichi Bubble Tea (Peachtree Corners) | Taichi Bubble Tea (UA Albany) | Taichi Bubble Tea (Victor) | Taichi Bubble Tea (Bel Air) | Taichi Bubble Tea (College Town) | Taichi Bubble Tea/Ramen/Hibachi (Milwaukee) | Taichi Bubble Tea (Syracuse) | Taichi Bubble Tea (Columbia Crossing Cir) | Taichi Bubble Tea (Broad St) | Tai Chi Bubble Tea (North Ave) | Taichi Bubble Tea (Irondequoit) | Taichi Bubble Tea (Mt Pleasant) | Taichi Bubble Tea (Marietta) | Taichi Bubble Tea (Jackson) | Taichi Bubble Tea (Henrietta) | Taichi Bubble Tea (Bronx) | TaiChi Bubble Tea (E 3rd St) | Taichi Bubble Tea (Glen Mills) | Taichi Bubble Tea (New Haven) | Taichi Bubble Tea (Chicago) | Taichi Bubble Tea (Pittsford) | Taichi Bubble Tea (Severna Park) | Taichi Bubble Tea (Watkins Glen) | Taichi Bubble Tea (Utica) | Taichi Bubble Tea (Crofton) | Taichi Bubble Tea (Sioux Falls) | Taichi Bubble Tea (Sacramento) | Taichi Bubble Tea (Dewitt) | Taichi Bubble Tea (Vestal) | Taichi Bubble Tea (Georgetown) | Taichi Bubble Tea (Stonybrook) | Tai Chi Bubble Tea (E State St) | Taichi Bubble Tea (Tonawanda) | Taichi Bubble Tea (Ithaca) | Taichi Bubble Tea (Nyack) | Taichi Bubble Tea (Annapolis) | Taichi Bubble Tea (Provo) | Taichi Bubble Tea (Sykesville) | Taichi Bubble Tea (Wichita) | Taichi Bubble Tea (Transit Road) | H89: 46063.641
A90: 161030 | B90: Tony | C90: Li | D90: liyu3231@gmail.com | E90: STORE OPERATOR | F90: 1083912 | G90: Taichi Bubble Tea (Niagara Falls) | H90: 46063.641
A91: 161030 | B91: Andy | C91: LIN | D91: aj41886@gmail.com | E91: ADMIN, MANAGER | F91: 25487498 | G91: Taichi Bubble Tea (E Broadway Blvd) | H91: 46063.641
A92: 161030 | B92: Dian | C92: Lin | D92: taichiteamiddletown@gmail.com | E92: MANAGER | F92: 40446895 | G92: Tai Chi Bubble Tea (Middletown) | H92: 46063.641
A93: 161030 | B93: Henry | C93: Lin | D93: watkinsglentaichi@gmail.com | E93: STORE OPERATOR | F93: 34631365 | G93: Taichi Bubble Tea (Watkins Glen) | H93: 46063.641
A94: 161030 | B94: HONGKAI | C94: LIN | D94: taichigreecemall@gmail.com | E94: MANAGER | F94: 2816430 | G94: Taichi Bubble Tea (Greece) | H94: 46063.641
A95: 161030 | B95: Jason | C95: Lin | D95: taichiatlantaga@gmail.com | E95: MANAGER | F95: 25806593 | G95: Taichi Bubble Tea (Peachtree Corners) | H95: 46063.641
A96: 161030 | B96: Jason | C96: Lin | D96: taichialbanyua@gmail.com | E96: MANAGER | F96: 25308292 | G96: Taichi Bubble Tea (UA Albany) | H96: 46063.641
A97: 161030 | B97: Lily | C97: Lin | D97: lily67616@gmail.com | E97: MANAGER | F97: 24463485 | G97: Taichi Bubble Tea (Sacramento) | H97: 46063.641
A98: 161030 | B98: Tom | C98: Lin | D98: taichidanbury@gmail.com | E98: MANAGER | F98: 3.0086866e+15 | G98: Taichi Bubble Tea (Danbury) | Taichi Bubble Tea (Nyack) | H98: 46063.641
A99: 161030 | B99: Tom | C99: Lin | D99: taichiteanyack@gmail.com | E99: MANAGER | F99: 30320691 | G99: Taichi Bubble Tea (Nyack) | H99: 46063.641
A100: 161030 | B100: Yan Juan | C100: Lin | D100: yanlin8686@gmail.com | E100: MANAGER | F100: 32844989 | G100: Taichi Bubble Tea (Bel Air) | H100: 46063.641
...
